<?xml version="1.0"?>
<robot name="simple_robot">

  <!-- Châssis -->
  <link name="base_link">
    <visual>
      <geometry>
        <box size="0.5 0.3 0.1"/> <!-- Dimensions du châssis -->
      </geometry>
      <material name="blue">
        <color rgba="0 0 1 1"/>
      </material>
    </visual>
  </link>

  <!-- Roue gauche -->
  <link name="left_wheel">
    <visual>
      <geometry>
        <cylinder radius="0.05" length="0.02"/>
      </geometry>
      <material name="black">
        <color rgba="0 0 0 1"/>
      </material>
    </visual>
  </link>

  <!-- Roue droite -->
  <link name="right_wheel">
    <visual>
      <geometry>
        <cylinder radius="0.05" length="0.02"/>
      </geometry>
      <material name="black">
        <color rgba="0 0 0 1"/>
      </material>
    </visual>
  </link>

  <!-- Joint du châssis à la roue gauche -->
  <joint name="left_wheel_joint" type="continuous">
    <parent link="base_link"/>
    <child link="left_wheel"/>
    <origin xyz="-0.2 0.1 0" rpy="0 1.5708 0"/>
    <axis xyz="0 1 0"/>
  </joint>

  <!-- Joint du châssis à la roue droite -->
  <joint name="right_wheel_joint" type="continuous">
    <parent link="base_link"/>
    <child link="right_wheel"/>
    <origin xyz="0.2 0.1 0" rpy="0 1.5708 0"/>
    <axis xyz="0 1 0"/>
  </joint>

</robot>

